<!-- HAL Model

    The state space is populated with joints in the order that they are
    defined in this file. The actuators also operate on joints.

    State-Space (name/joint/parameter):
        - rootx     slider      position (m)
        - rootz     slider      position (m)
        - rooty     hinge       angle (rad)
        - spine     hinge       angle (rad)
        - bthigh    hinge       angle (rad)
        - bshin     hinge       angle (rad)
        - fthigh    hinge       angle (rad)
        - fshin     hinge       angle (rad)
        - rootx     slider      velocity (m/s)
        - rootz     slider      velocity (m/s)
        - rooty     hinge       angular velocity (rad/s)
        - spine     hinge       angular velocity (rad/s)
        - bthigh    hinge       angular velocity (rad/s)
        - bshin     hinge       angular velocity (rad/s)
        - fthigh    hinge       angular velocity (rad/s)
        - fshin     hinge       angular velocity (rad/s)

    Actuators (name/actuator/parameter):
        - spine     hinge       torque (N m)
        - bthigh    hinge       torque (N m)
        - bshin     hinge       torque (N m)
        - fthigh    hinge       torque (N m)
        - fshin     hinge       torque (N m)

-->
<mujoco model="cheetah">
    <compiler angle="radian" coordinate="local" inertiafromgeom="true" settotalmass="14"/>

    <default>
        <joint armature=".1" damping=".01" limited="true" solimplimit="0 .8 .03" solreflimit=".02 1" stiffness="8"/>
        <geom conaffinity="0" condim="3" contype="1" friction=".4 .1 .1" rgba="0.8 0.6 .4 1" solimp="0.0 0.8 0.01" solref="0.02 1"/>
        <motor ctrllimited="true" ctrlrange="-1 1"/>
    </default>

    <size nstack="300000" nuser_geom="1"/>
    <option gravity="0 0 -9.81" timestep="0.01"/>
    
    <asset>
        <mesh name="thigh_mesh" file="meshes/thigh.stl" scale="0.001 0.001 0.001"/>
        <mesh name="shin_mesh" file="meshes/shin.stl" scale="0.001 0.001 0.001"/>

        <texture type="skybox" builtin="gradient" rgb1=".3 .5 .7" rgb2="0 0 0" width="32" height="512"/>
        <texture name="body" type="cube" builtin="flat" mark="cross" width="128" height="128" rgb1="0.8 0.6 0.4" rgb2="0.8 0.6 0.4" markrgb="1 1 1" random="0.01"/>
        <material name="body" texture="body" texuniform="true" rgba="0.8 0.6 .4 1"/>
        <texture name="grid" type="2d" builtin="checker" width="512" height="512" rgb1=".1 .2 .3" rgb2=".2 .3 .4"/>
        <material name="grid" texture="grid" texrepeat="4 4" texuniform="true" reflectance=".0"/>
    </asset>

    <worldbody>
        <light name="spotlight" mode="targetbodycom" target="torso" diffuse=".8 .8 .8" specular="0.3 0.3 0.3" pos="0 -6 4" cutoff="30"/>
        <geom conaffinity="1" condim="3" material="grid" name="floor" pos="0 0 0" size="0 0 .05" type="plane"/>
        
        <body name="torso" pos="0 0 .7">
            <camera name="track" mode="trackcom" pos="0 -2 0.1" xyaxes="1 0 0 0 0 1"/>
            <joint armature="0" axis="1 0 0" damping="0" limited="false" name="rootx" pos="0 0 0" stiffness="0" type="slide"/>
            <joint armature="0" axis="0 0 1" damping="0" limited="false" name="rootz" pos="0 0 0" stiffness="0" type="slide"/>
            <joint armature="0" axis="0 1 0" damping="0" limited="false" name="rooty" pos="0 0 0" stiffness="0" type="hinge"/>
            <geom quat="0 0 0.7071068 0.7071068" type="cylinder" name="front_torso_center_geom" size="0.05 0.025" pos="0 0 0"  rgba="0.8 0.5 0.2 1"/>

            <body name="front_torso" pos="0 0 0">
                <joint name="spine" damping="0.5" type="hinge" axis="0 1 0" pos="0 0 0" range="-2 2" stiffness="8"/>
                <geom fromto="0 0 0 .195586 0 0" rgba="0.141 0.141 0.141 1" name="front_torso_geom" size="0.01" type="capsule"/>
                <geom quat="0 0 0.7071068 0.7071068" rgba="0.141 0.141 0.141 1" type="cylinder" size="0.046 0.01" pos="0.119488 0.001 0" friction="1.0 .1 .1"/>

                <body name="fthigh" pos=".195586 0 0">
                    <joint axis="0 1 0" damping="0.3" name="fthigh" pos="0 0 0" range="-3 3" stiffness="2" type="hinge"/>
                    <geom quat="0 0 0.7071068 0.7071068" rgba="0.329 0.329 0.329 1" name="fthigh_pully_geom" type="cylinder" size="0.0585 0.01" pos="0.01 0 0"/>
                    <geom quat="0 0 0.7071068 0.7071068" rgba="0.329 0.329 0.329 1" name="fthigh_geom" pos="0.01 -0.02 0" type="mesh" mesh="thigh_mesh" friction="1.0 .1 .1"/> 
                    
                    <body name="fshin" pos="0.01 -0.02 0">
                        <joint axis="0 1 0" damping="0.3" name="fshin" pos="0 0 -0.175026" range="-2.8 2.8" stiffness="2" type="hinge"/>
                        <geom quat="0 0 0.7071068 0.7071068" name="fshin_geom" pos="0 0 0" rgba="0.51 0.51 0.51 1" type="mesh" mesh="shin_mesh" friction="2.5 .1 .1"/>
                    </body>

                </body>
            </body>

            <body name="back_torso" pos="0 0 0">
                <geom fromto="-.195586 0 0 0 0 0" rgba="0.141 0.141 0.141 1" name="back_torso_geom" size="0.01" type="capsule"/>
                <geom quat="0 0 0.7071068 0.7071068" rgba="0.141 0.141 0.141 1" type="cylinder" size="0.046 0.01" pos="-0.119488 0.001 0"/>

                <body name="bthigh" pos="-.195586 0 0">
                    <joint axis="0 1 0" damping="0.3" name="bthigh" pos="0 0 0" range="-3 3" stiffness="2" type="hinge"/>
                    <geom quat="0 0 0.7071068 0.7071068" rgba="0.329 0.329 0.329 1" name="bthigh_pully_geom" type="cylinder" size="0.0585 0.01" pos="-0.01 0 0" />
                    <geom quat="0 0 0.7071068 0.7071068" rgba="0.329 0.329 0.329 1" name="bthigh_geom" pos="-0.01 -0.02 0" type="mesh" mesh="thigh_mesh" friction="1.0 .1 .1"/> 

                    <body name="bshin" pos="-0.01 -0.02 0">
                        <joint axis="0 1 0" damping="0.3" name="bshin" pos="0 0 -0.175026" range="-2.8 2.8" stiffness="2" type="hinge"/>
                        <geom quat="0 0 0.7071068 0.7071068" name="bshin_geom" pos="0 0 0" rgba="0.51 0.51 0.51 1" type="mesh" mesh="shin_mesh" friction="2.5 .1 .1"/>
                    </body>

                </body>
            </body>

        </body>
    </worldbody>

    <actuator>
        <motor gear="15" joint="spine" name="spine"/> <!-- Reduced from 100 -->
        <motor gear="20" joint="bthigh" name="bthigh"/> <!-- Reduced from 120 -->
        <motor gear="25" joint="bshin" name="bshin"/> <!-- Reduced from 90 -->
        <motor gear="20" joint="fthigh" name="fthigh"/> <!-- Kept the same for demonstration, adjust as needed -->
        <motor gear="25" joint="fshin" name="fshin"/> <!-- Reduced from 60 -->
    </actuator>

</mujoco>
